<?xml version="1.0"?>
<robot  xmlns:xacro="http://www.ros.org/wiki/xacro" name="mycobot_280pi" >
	

  <link name="g_base">
    <visual>
      <geometry>
        <mesh filename="file://$(find mycobot_280pi_description)/meshes/G_base.dae"/>
      </geometry>
      <origin xyz = "0.0 0 -0.03" rpy = "0 0 1.5708"/>
    </visual>
    <collision>
      <geometry>
        <mesh filename="file://$(find mycobot_280pi_description)/meshes/G_base.dae"/>
      </geometry>
      <origin xyz = "0.0 0 -0.03" rpy = "0 0 1.5708"/>
    </collision>
		<inertial>
			<origin xyz="0 0 0.0" rpy="0 0 0"/>
			<mass value="0.33"/>
			<inertia
				ixx="0.000784" ixy="0.0" ixz="0.0"
				iyy="0.000867" iyz="0.0"
				izz="0.001598"/>
		</inertial>    
  </link>

  <link name="joint1">
    <visual>
      <geometry>
	     <!--- 0.0 0 -0.04  1.5708 3.14159-->
       <mesh filename="file://$(find mycobot_280pi_description)/meshes/link1.dae"/>
      </geometry>
    <origin xyz = "0.0 0 0 " rpy = " 0 0 0"/>
    </visual>
    <collision>
      <geometry>
	     <!--- 0.0 0 -0.04  1.5708 3.14159-->
       <mesh filename="file://$(find mycobot_280pi_description)/meshes/link1.dae"/>
      </geometry>
    <origin xyz = "0.0 0 0 " rpy = " 0 0 0"/>
    </collision>
		<inertial>
			<origin xyz="0 0 0.0" rpy="0 0 0"/>
			<mass value="0.12"/>
			<inertia
				ixx="0.000148" ixy="0.0" ixz="0.0"
				iyy="0.000148" iyz="0.0"
				izz="0.000096"/>
		</inertial>    
  </link>

  <link name="joint2">
    <visual>
      <geometry>
       <mesh filename="file://$(find mycobot_280pi_description)/meshes/link2.dae"/>
      </geometry>
    <origin xyz = "0.0 0 -0.06096 " rpy = " 0 0 -1.5708"/>
    </visual>
      <collision>
      <geometry>
       <mesh filename="file://$(find mycobot_280pi_description)/meshes/link2.dae"/>
      </geometry>
    <origin xyz = "0.0 0 -0.06096 " rpy = " 0 0 -1.5708"/>
    </collision>
		<inertial>
			<origin xyz="0 0 0.0" rpy="0 0 0"/>
			<mass value="0.19"/>
			<inertia
				ixx="0.000148" ixy="0.0" ixz="0.0"
				iyy="0.000148" iyz="0.0"
				izz="0.000096"/>
		</inertial>    
  </link>


  <link name="joint3">
    <visual>
      <geometry>
       
       <mesh filename="file://$(find mycobot_280pi_description)/meshes/link3.dae"/>
      </geometry>
    <origin xyz = "0.0 0 0.03256 " rpy = " 0 -1.5708 0"/>
    </visual>
      <collision>
        <geometry>
       <mesh filename="file://$(find mycobot_280pi_description)/meshes/link3.dae"/>
      </geometry>
    <origin xyz = "0.0 0 0.03256 " rpy = " 0 -1.5708 0"/>
    </collision>
		<inertial>
			<origin xyz="0 0 0.0" rpy="0 0 0"/>
		  	<mass value="0.16"/>
			<inertia
			  ixx="0.000148" ixy="0.0" ixz="0.0"
			  iyy="0.000148" iyz="0.0"
			  izz="0.000096"/>
		</inertial>    
  </link>


  <link name="joint4">
    <visual>
      <geometry>
       <!--- 0.0 0 -0.04 -->
       <mesh filename="file://$(find mycobot_280pi_description)/meshes/link4.dae"/>
      </geometry>
    <origin xyz = "0.0 0 0.03056 " rpy = " 0 -1.5708 0"/>
    </visual>
      <collision>
      <geometry>
       <!--- 0.0 0 -0.04 -->
       <mesh filename="file://$(find mycobot_280pi_description)/meshes/link4.dae"/>
      </geometry>
    <origin xyz = "0.0 0 0.03056 " rpy = " 0 -1.5708 0"/>
    </collision>
		<inertial>
		  	<origin xyz="0 0 0.0" rpy="0 0 0"/>
			<mass value="0.124"/>
			<inertia
			  	ixx="0.000103" ixy="0.0" ixz="0.0"
			  	iyy="0.000103" iyz="0.0"
			  	izz="0.000096"/>
		</inertial>    
  </link>




<link name="joint5">
    <visual>
      <geometry>
       <!--- 0.0 0 -0.04 -->
       <mesh filename="file://$(find mycobot_280pi_description)/meshes/link5.dae"/>
      </geometry>
    <origin xyz = "0.0 0 -0.03356 " rpy = "-1.5708 0 0"/>
    </visual>
      <collision>
      <geometry>
       <!--- 0.0 0 -0.04 -->
       <mesh filename="file://$(find mycobot_280pi_description)/meshes/link5.dae"/>
      </geometry>
    <origin xyz = "0.0 0 -0.03356 " rpy = "-1.5708 0 0"/>
    </collision>
		<inertial>
			<origin xyz="0 0 0.0" rpy="0 0 0"/>
		  	<mass value="0.11"/>
			<inertia
			  ixx="0.000103" ixy="0.0" ixz="0.0"
			  iyy="0.000103" iyz="0.0"
			  izz="0.000096"/>
		</inertial>    
  </link>


  <link name="joint6">
    <visual>
      <geometry>
       <!--- 0.0 0 -0.04 -->
       <mesh filename="file://$(find mycobot_280pi_description)/meshes/link6.dae"/>
      </geometry>
    <origin xyz = "0 0.00 -0.038 " rpy = " 0 0 0"/>
    </visual>
      <collision>
      <geometry>
       <!--- 0.0 0 -0.04 -->
       <mesh filename="file://$(find mycobot_280pi_description)/meshes/link6.dae"/>
      </geometry>
    <origin xyz = "0 0.00 -0.038 " rpy = " 0 0 0"/>
    </collision>
		<inertial>
			<origin xyz="0 0 0.0" rpy="0 0 0"/>
		  	<mass value="0.0739"/>
			<inertia
			  ixx="0.00006649" ixy="0.0" ixz="0.0"
			  iyy="0.00006649" iyz="0.0"
			  izz="0.000096"/>
		</inertial>    
  </link>


  <link name="joint6_flange">
    <visual>
      <geometry>
       <!--- 0.0 0 -0.04 -->
       <mesh filename="file://$(find mycobot_280pi_description)/meshes/link7.dae"/>
      </geometry>
    <origin xyz = "0.0 0 -0.012 " rpy = " 0 0 0"/>
    </visual>
      <collision>
      <geometry>
       <!--- 0.0 0 -0.04 -->
       <mesh filename="file://$(find mycobot_280pi_description)/meshes/link7.dae"/>
      </geometry>
    <origin xyz = "0.0 0 -0.012 " rpy = " 0 0 0"/>
    </collision>
		<inertial>
			<origin xyz="0 0 0.0" rpy="0 0 0"/>
		  	<mass value="0.035"/>
		  	<inertia
				ixx="0.0000149" ixy="0.0" ixz="0.0"
				iyy="0.0000149" iyz="0.0"
				izz="0.0000196"/>
		</inertial>    
  </link>


  <joint name="g_base_to_joint1" type="fixed">
    <axis xyz="0 0 0"/>
    <limit effort = "1000.0" lower = "-3.14" upper = "3.14159" velocity = "0"/>
    <parent link="g_base"/>
    <child link="joint1"/>
    <origin xyz= "0 0 0" rpy = "0 0 0"/>  
  </joint>


  <joint name="joint2_to_joint1" type="revolute">
    <axis xyz="0 0 1"/>
    <limit effort = "56.0" lower = "-3.14" upper = "3.14159" velocity = "2.79"/>
    <parent link="joint1"/>
    <child link="joint2"/>
    <origin xyz= "0 0 0.13956" rpy = "0 0 0"/>  
    <dynamics damping="0.0" friction="0.0"/>
  </joint>


  <joint name="joint3_to_joint2" type="revolute">
    <axis xyz="0 0 1"/>
    <limit effort = "56.0" lower = "-3.14" upper = "3.14159" velocity = "2.79"/>
    <parent link="joint2"/>
    <child link="joint3"/>
    <origin xyz= "0 0 -0.001" rpy = "0 1.5708 -1.5708"/>  
    <dynamics damping="0.0" friction="0.0"/>
  </joint>


  <joint name="joint4_to_joint3" type="revolute">
    <axis xyz=" 0 0 1"/>
    <limit effort = "56.0" lower = "-3.14" upper = "3.14159" velocity = "2.79"/>
    <parent link="joint3"/>
    <child link="joint4"/>
    <origin xyz= "  -0.1104 0 0   " rpy = "0 0 0"/>  
    <dynamics damping="0.0" friction="0.0"/>
  </joint>



  <joint name="joint5_to_joint4" type="revolute">
    <axis xyz=" 0 0 1"/>
    <limit effort = "56.0" lower = "-3.14" upper = "3.14159" velocity = "2.79"/>
    <parent link="joint4"/>
    <child link="joint5"/>
    <origin xyz= "-0.096 0 0.06462" rpy = "0 0 -1.5708"/>  
    <dynamics damping="0.0" friction="0.0"/>
  </joint>

  <joint name="joint6_to_joint5" type="revolute">
    <axis xyz="0 0 1"/>
    <limit effort = "56.0" lower = "-3.14" upper = "3.14159" velocity = "2.79"/>
    <parent link="joint5"/>
    <child link="joint6"/>
    <origin xyz= "0 -0.07318 0" rpy = "1.5708 -1.5708 0"/>  
    <dynamics damping="0.0" friction="0.0"/>
  </joint>

  <joint name="joint6output_to_joint6" type="revolute">
    <axis xyz="0 0 1"/>
    <limit effort = "56.0" lower = "-3.14" upper = "3.14159" velocity = "2.79"/>
    <parent link="joint6"/>
    <child link="joint6_flange"/>
    <origin xyz= "0 0.0456 0" rpy = "-1.5708 0 0"/>  
    <dynamics damping="0.0" friction="0.0"/>
  </joint>


<!-- Gripper -->

	<link name="gripper_base">
		<inertial>
			<origin xyz="0 0 0.0" rpy="0 0 0"/>
		  	<mass value="0.07"/>
		  	<inertia
				ixx="0.000010725" ixy="0.0" ixz="0.0"
				iyy="0.000014392" iyz="0.0"
				izz="0.000018517"/>
		</inertial>
		<visual>
		  	<geometry>
				<mesh filename="file://$(find mycobot_280pi_description)/meshes/gripper_base.dae"/>
		  	</geometry>
		  	<origin xyz = "0.0 0.0 -0.012" rpy = "0 0 0"/>
		</visual>
		<collision>
		   	<geometry>	
		   		<box size="0.01 0.01 0.01"/>
		  	</geometry>
		  	<origin xyz = "0.0 0.0 0.0" rpy = "0 0 0"/>
		</collision>
	</link>

	<link name="gripper_left1">
		<inertial>
			<origin xyz="0 0 0.0" rpy="0 0 0"/>
		  	<mass value="0.007"/>
		  	<inertia
				ixx="1e-6" ixy="0.0" ixz="0.0"
				iyy="1e-6" iyz="0.0"
				izz="1e-6"/>
		</inertial>
		<visual>
		  	<geometry>
		  		<mesh filename="file://$(find mycobot_280pi_description)/meshes/gripper_left1.dae"/>
		  	</geometry>
			<origin xyz = "0.039 -0.0133 -0.012 " rpy = " 0 0 0"/>
		</visual>
		<collision>
		  	<geometry>
		   		<box size="0.01 0.01 0.01"/>
		  	</geometry>
			<origin xyz = "0.013 0.042 -0.010 " rpy = " 0 0 0"/>
		</collision>
	</link>
	
	<link name="gripper_left2">
		<inertial>
			<origin xyz="0 0 0.0" rpy="0 0 0"/>
		  	<mass value="0.007"/>
		  	<inertia
				ixx="1e-6" ixy="0.0" ixz="0.0"
				iyy="1e-6" iyz="0.0"
				izz="1e-6"/>
		</inertial>
		<visual>
		  	<geometry>
		   		<mesh filename="file://$(find mycobot_280pi_description)/meshes/gripper_left2.dae"/>
		  	</geometry>
			<origin xyz = "0.005 -0.0195 -0.012 " rpy = " 0 0 0"/>
		</visual>
		<collision>
		  	<geometry>
		   		<box size="0.01 0.01 0.01"/>
		  	</geometry>
			<origin xyz = "-0.025 0.0 -0.010 " rpy = " 0 0 0"/>
		</collision>
	</link>
	
	<link name="gripper_left3">
		<inertial>
			<origin xyz="0 0 0.0" rpy="0 0 0"/>
		  	<mass value="0.007"/>
		  	<inertia
				ixx="1e-6" ixy="0.0" ixz="0.0"
				iyy="1e-6" iyz="0.0"
				izz="1e-6"/>
		</inertial>
		<visual>
		  	<geometry>
		   		<mesh filename="file://$(find mycobot_280pi_description)/meshes/gripper_left3.dae"/>
		  	</geometry>
		<origin xyz = "0.012 0.0025 -0.012 " rpy = " 0 0 0"/>
		</visual>
		<collision>
		  	<geometry>
		   		<box size="0.01 0.01 0.01"/>
		  	</geometry>
			<origin xyz = "-0.014 0.005 0.005 " rpy = " 0 0 0"/>
		</collision>
	</link>
	
	<link name="gripper_right1">
		<inertial>
			<origin xyz="0 0 0.0" rpy="0 0 0"/>
		  	<mass value="0.007"/>
		  	<inertia
				ixx="1e-6" ixy="0.0" ixz="0.0"
				iyy="1e-6" iyz="0.0"
				izz="1e-6"/>
		</inertial>
		<visual>
			<geometry>
		   		<mesh filename="file://$(find mycobot_280pi_description)/meshes/gripper_right1.dae"/>
		  	</geometry>
			<origin xyz = "-0.039 -0.0133 -0.012 " rpy = " 0 0 0"/>
		</visual>
		<collision>
		  	<geometry>
		   		<box size="0.01 0.01 0.01"/>
		  	</geometry>
			<origin xyz = "-0.013 0.042 -0.010 " rpy = " 0 0 0"/>
		</collision>
	</link>
	
	<link name="gripper_right2">
		<inertial>
			<origin xyz="0 0 0.0" rpy="0 0 0"/>
		  	<mass value="0.007"/>
		  	<inertia
				ixx="1e-6" ixy="0.0" ixz="0.0"
				iyy="1e-6" iyz="0.0"
				izz="1e-6"/>
		</inertial>
		<visual>
			<geometry>
		   		<mesh filename="file://$(find mycobot_280pi_description)/meshes/gripper_right2.dae"/>
		 	</geometry>
			<origin xyz = "-0.005 -0.0195 -0.012 " rpy = " 0 0 0"/>
		</visual>
		<collision>
		  	<geometry>
		   		<box size="0.01 0.01 0.01"/>
		  	</geometry>
			<origin xyz = "0.025 0.0 -0.010 " rpy = " 0 0 0"/>
		</collision>
	</link>
	
	<link name="gripper_right3">
		<inertial>
			<origin xyz="0 0 0.0" rpy="0 0 0"/>
		  	<mass value="0.007"/>
		  	<inertia
				ixx="1e-6" ixy="0.0" ixz="0.0"
				iyy="1e-6" iyz="0.0"
				izz="1e-6"/>
		</inertial>
		<visual>
			<geometry>
		   		<mesh filename="file://$(find mycobot_280pi_description)/meshes/gripper_right3.dae"/>
			</geometry>
			<origin xyz = "-0.012 0.0025 -0.012 " rpy = " 0 0 0"/>
		</visual>
		<collision>
		  	<geometry>
		   		<box size="0.01 0.01 0.01"/>
		  	</geometry>
			<origin xyz = "0.014 0.005 0.005 " rpy = " 0 0 0"/>
		</collision>
	</link>


	<joint name="joint6flange_to_gripper_base" type="fixed">
		<parent link="joint6_flange"/>
		<child link="gripper_base"/>
		<origin xyz= "0 0 0.034" rpy = "1.579 0 0"/>
	</joint>

	<joint name="gripper_controller" type="revolute">
		<axis xyz="0 0 1"/>
		<limit effort = "1000" lower = "-0.8" upper = "0.15" velocity = "0" />
		<parent link="gripper_base"/>
		<child link="gripper_left3"/>
		<origin xyz= "-0.012 0.005 0" rpy = "0 0 0"/> 
        <dynamics damping="0.0" friction="0.0"/>
	</joint>
	
	<joint name="gripper_base_to_gripper_left2" type="revolute">
		<axis xyz="0 0 1"/>
		<limit effort = "1000" lower = "-0.8" upper = "0.5" velocity = "0" />
		<parent link="gripper_base"/>
		<child link="gripper_left2"/>
		<origin xyz= "-0.005 0.027 0" rpy = "0 0 0"/> 
		<mimic joint="gripper_controller" multiplier="1.0" offset="0" />
        <dynamics damping="0.0" friction="0.0"/>
	</joint>
	
	<joint name="gripper_left3_to_gripper_left1" type="revolute">
		<axis xyz="0 0 1"/>
		<limit effort = "1000" lower = "-0.5" upper = "0.5" velocity = "0" />
		<parent link="gripper_left3"/>
		<child link="gripper_left1"/>
		<origin xyz= "-0.027 0.016 0" rpy = "0 0 0"/> 
		<mimic joint="gripper_controller" multiplier="-1.0" offset="0" />
        <dynamics damping="0.0" friction="0.0"/>
	</joint>
	
	<joint name="gripper_base_to_gripper_right3" type="revolute">
		<axis xyz="0 0 1"/>
		<limit effort = "1000" lower = "-0.15" upper = "0.7" velocity = "0" />
		<parent link="gripper_base"/>
		<child link="gripper_right3"/>
		<origin xyz= "0.012 0.005 0" rpy = "0 0 0"/> 
		<mimic joint="gripper_controller" multiplier="-1.0" offset="0" />
        <dynamics damping="0.0" friction="0.0"/>
	</joint>
	
	<joint name="gripper_base_to_gripper_right2" type="revolute">
		<axis xyz="0 0 1"/>
		<limit effort = "1000" lower = "-0.5" upper = "0.8" velocity = "0" />
		<parent link="gripper_base"/>
		<child link="gripper_right2"/>
		<origin xyz= "0.005 0.027 0" rpy = "0 0 0"/> 
		<mimic joint="gripper_controller" multiplier="-1.0" offset="0" />
        <dynamics damping="0.0" friction="0.0"/>
	</joint>
	
	<joint name="gripper_right3_to_gripper_right1" type="revolute">
		<axis xyz="0 0 1"/>
		<limit effort = "1000" lower = "-0.5" upper = "0.5" velocity = "0" />
		<parent link="gripper_right3"/>
		<child link="gripper_right1"/>
		<origin xyz= "0.027 0.016 0" rpy = "0 0 0"/> 
		<mimic joint="gripper_controller" multiplier="1.0" offset="0" />
        <dynamics damping="0.0" friction="0.0"/>
	</joint>




</robot>
