<?xml version="1.0" ?>
<robot xmlns:xacro="http://wiki.ros.org/xacro" name="mycobot_280">
	<link name="world"/>


	<xacro:property name="M_PI" value="3.1415926535897931" />
  
	<xacro:property name="d435_cam_width" value="0.090"/>
	<xacro:property name="d435_cam_height" value="0.025"/>
	<xacro:property name="d435_cam_depth" value="0.02505"/>
	
	<xacro:property name="d435_cam_depth_to_infra1_offset" value="0.0"/>
	<xacro:property name="d435_cam_depth_to_infra2_offset" value="-0.050"/>
	<xacro:property name="d435_cam_depth_to_color_offset" value="0.015"/>
	
	<xacro:property name="camera_tilt_angle_deg" value="45"/>  


	<xacro:property name="effort" value="5.0"/>
	<xacro:property name="velocity" value="2.792527"/>

	<link name="base_link">

		<inertial>
			<origin xyz="0 0 0.0" rpy="0 0 0"/>
			<mass value="0.33"/>
			<inertia
				ixx="0.000784" ixy="0.0" ixz="0.0"
				iyy="0.000867" iyz="0.0"
				izz="0.001598"/>
		</inertial>
		<visual>
			<geometry>
				<mesh filename="file://$(find mycobot_description)/meshes/mycobot_280/base_link.dae"/>
			</geometry>
			<origin xyz = "0.0 0 -0.03" rpy = "0 0 ${pi/2}"/>
		</visual>
		<collision>
			<geometry>
				<mesh filename="file://$(find mycobot_description)/meshes/mycobot_280/base_link.dae"/>
			</geometry>
			<origin xyz = "0.0 0 -0.03" rpy = "0 0 ${pi/2}"/>
		</collision>
	</link>


	<link name="link1">

		<inertial>

			<origin xyz="0 0 0.0" rpy="0 0 0"/>

			<mass value="0.12"/>

			<inertia
				ixx="0.000148" ixy="0.0" ixz="0.0"
				iyy="0.000148" iyz="0.0"
				izz="0.000096"/>
		</inertial>

		<visual>

			<geometry>

				<mesh filename="file://$(find mycobot_description)/meshes/mycobot_280/link1.dae"/>
			</geometry>

			<origin xyz = "0.0 0 0 " rpy = " 0 0 ${-pi/2}"/>
		</visual>

		<collision>
			<geometry>
				<mesh filename="file://$(find mycobot_description)/meshes/mycobot_280/link1.dae"/>
			</geometry>
			<origin xyz = "0.0 0 0.0 " rpy = " 0 0 ${-pi/2}"/>
		</collision>
	</link>
	
	<link name="link2">
		<inertial>
			<origin xyz="0 0 0.0" rpy="0 0 0"/>
			<mass value="0.19"/>
			<inertia
				ixx="0.000148" ixy="0.0" ixz="0.0"
				iyy="0.000148" iyz="0.0"
				izz="0.000096"/>
		</inertial>
		<visual>
			<geometry>
				<mesh filename="file://$(find mycobot_description)/meshes/mycobot_280/link2.dae"/>
			</geometry>
			<origin xyz = "0.0 0 -0.06096" rpy = " 0 0 ${-pi/2}"/>
		</visual>
		<collision>
			<geometry>
				<mesh filename="file://$(find mycobot_description)/meshes/mycobot_280/link2.dae"/>
			</geometry>
			<origin xyz = "0.0 0 -0.06096" rpy = " 0 0 ${-pi/2}"/>
		</collision>
	</link>

	<link name="link3">
		<inertial>
			<origin xyz="0 0 0.0" rpy="0 0 0"/>
		  	<mass value="0.16"/>
			<inertia
			  ixx="0.000148" ixy="0.0" ixz="0.0"
			  iyy="0.000148" iyz="0.0"
			  izz="0.000096"/>
		</inertial>
		<visual>
		  	<geometry>
		   		<mesh filename="file://$(find mycobot_description)/meshes/mycobot_280/link3.dae"/>
		  	</geometry>
			<origin xyz = "0.0 0 0.03256 " rpy = " 0 ${-pi/2} 0"/>
		</visual>
		<collision>
		  	<geometry>
		   		<mesh filename="file://$(find mycobot_description)/meshes/mycobot_280/link3.dae"/>
		  	</geometry>
		  	<origin xyz = "0.00 0 0.03256 " rpy = " 0 ${-pi/2} 0"/>
		</collision>
	</link>

	<link name="link4">
		<inertial>
		  	<origin xyz="0 0 0.0" rpy="0 0 0"/>
			<mass value="0.124"/>
			<inertia
			  	ixx="0.000103" ixy="0.0" ixz="0.0"
			  	iyy="0.000103" iyz="0.0"
			  	izz="0.000096"/>
		</inertial>
		<visual>
			<geometry>
				<mesh filename="file://$(find mycobot_description)/meshes/mycobot_280/link4.dae"/>
			</geometry>
			<origin xyz = "0.0 0 0.03056 " rpy = " 0 ${-pi/2} 0"/>
		</visual>
		<collision>
			<geometry>
				<mesh filename="file://$(find mycobot_description)/meshes/mycobot_280/link4.dae"/>
			</geometry>
			<origin xyz = "0.0 0 0.03056 " rpy = " 0 ${-pi/2} 0"/>
		</collision>
	</link>

	<link name="link5">
		<inertial>
			<origin xyz="0 0 0.0" rpy="0 0 0"/>
		  	<mass value="0.11"/>
			<inertia
			  ixx="0.000103" ixy="0.0" ixz="0.0"
			  iyy="0.000103" iyz="0.0"
			  izz="0.000096"/>
		</inertial>
		<visual>
		  	<geometry>
				<mesh filename="file://$(find mycobot_description)/meshes/mycobot_280/link5.dae"/>
		  	</geometry>
		  	<origin xyz = "0.0 0 -0.03356 " rpy = "${-pi/2} 0 0"/>
		</visual>
		<collision>
		   	<geometry>	
		   		<mesh filename="file://$(find mycobot_description)/meshes/mycobot_280/link5.dae"/>
		  	</geometry>
		  	<origin xyz = "0.0 0 -0.03356 " rpy = "${-pi/2} 0 0"/>
		</collision>
	</link>

	<link name="link6">
		<inertial>
			<origin xyz="0 0 0.0" rpy="0 0 0"/>
		  	<mass value="0.0739"/>
			<inertia
			  ixx="0.00006649" ixy="0.0" ixz="0.0"
			  iyy="0.00006649" iyz="0.0"
			  izz="0.000096"/>
		</inertial>
		<visual>
		  	<geometry>
				<mesh filename="file://$(find mycobot_description)/meshes/mycobot_280/link6.dae"/>
		  	</geometry>
		  	<origin xyz = "0 0.00 -0.038" rpy = "0 0 0"/>
		</visual>
		<collision>
		   	<geometry>	
		   		<mesh filename="file://$(find mycobot_description)/meshes/mycobot_280/link6.dae"/>
		  	</geometry>
		  	<origin xyz = "0 0.00 -0.038" rpy = "0 0 0"/>
		</collision>
	</link>

	<link name="link6_flange">
		<inertial>
			<origin xyz="0 0 0.0" rpy="0 0 0"/>
		  	<mass value="0.035"/>
		  	<inertia
				ixx="0.0000149" ixy="0.0" ixz="0.0"
				iyy="0.0000149" iyz="0.0"
				izz="0.0000196"/>
		</inertial>
		<visual>
		  	<geometry>
				<mesh filename="file://$(find mycobot_description)/meshes/mycobot_280/link7.dae"/>
		  	</geometry>
		  	<origin xyz = "0.0 0 -0.012 " rpy = "0 0 0"/>
		</visual>
		<collision>
		   	<geometry>	
		   		<mesh filename="file://$(find mycobot_description)/meshes/mycobot_280/link7.dae"/>
		  	</geometry>
		  	<origin xyz = "0.0 0 -0.012 " rpy = "0 0 0"/>
		</collision>
	</link>

	<link name="gripper_base">
		<inertial>
			<origin xyz="0 0 0.0" rpy="0 0 0"/>
		  	<mass value="0.07"/>
		  	<inertia
				ixx="0.000010725" ixy="0.0" ixz="0.0"
				iyy="0.000014392" iyz="0.0"
				izz="0.000018517"/>
		</inertial>
		<visual>
		  	<geometry>
				<mesh filename="file://$(find mycobot_description)/meshes/mycobot_280/gripper_base.dae"/>
		  	</geometry>
		  	<origin xyz = "0.0 0.0 -0.012" rpy = "0 0 0"/>
		</visual>
		<collision>
		   	<geometry>	
		   		<mesh filename="file://$(find mycobot_description)/meshes/mycobot_280/gripper_base.dae"/>
		  	</geometry>
		  	<origin xyz = "0.0 0.0 -0.012" rpy = "0 0 0"/>
		</collision>
	</link>

	<link name="gripper_left1">
		<inertial>
			<origin xyz="0 0 0.0" rpy="0 0 0"/>
		  	<mass value="0.007"/>
		  	<inertia
				ixx="1e-6" ixy="0.0" ixz="0.0"
				iyy="1e-6" iyz="0.0"
				izz="1e-6"/>
		</inertial>
		<visual>
		  	<geometry>
		  		<mesh filename="file://$(find mycobot_description)/meshes/mycobot_280/gripper_left1.dae"/>
		  	</geometry>
			<origin xyz = "0.039 -0.0133 -0.012 " rpy = " 0 0 0"/>
		</visual>
		<collision>
		  	<geometry>
		   		<mesh filename="file://$(find mycobot_description)/meshes/mycobot_280/gripper_left1.dae"/>
		  	</geometry>
			<origin xyz = "0.039 -0.0133 -0.012 " rpy = " 0 0 0"/>
		</collision>
	</link>
	
	<link name="gripper_left2">
		<inertial>
			<origin xyz="0 0 0.0" rpy="0 0 0"/>
		  	<mass value="0.007"/>
		  	<inertia
				ixx="1e-6" ixy="0.0" ixz="0.0"
				iyy="1e-6" iyz="0.0"
				izz="1e-6"/>
		</inertial>
		<visual>
		  	<geometry>
		   		<mesh filename="file://$(find mycobot_description)/meshes/mycobot_280/gripper_left2.dae"/>
		  	</geometry>
			<origin xyz = "0.005 -0.0195 -0.012 " rpy = " 0 0 0"/>
		</visual>
		<collision>
		  	<geometry>
		   		<mesh filename="file://$(find mycobot_description)/meshes/mycobot_280/gripper_left2.dae"/>
		  	</geometry>
				<origin xyz = "0.005 -0.0195 -0.012 " rpy = " 0 0 0"/>
		</collision>
	</link>
	
	<link name="gripper_left3">
		<inertial>
			<origin xyz="0 0 0.0" rpy="0 0 0"/>
		  	<mass value="0.007"/>
		  	<inertia
				ixx="1e-6" ixy="0.0" ixz="0.0"
				iyy="1e-6" iyz="0.0"
				izz="1e-6"/>
		</inertial>
		<visual>
		  	<geometry>
		   		<mesh filename="file://$(find mycobot_description)/meshes/mycobot_280/gripper_left3.dae"/>
		  	</geometry>
		<origin xyz = "0.012 0.0025 -0.012 " rpy = " 0 0 0"/>
		</visual>
		<collision>
		  	<geometry>
		   		<mesh filename="file://$(find mycobot_description)/meshes/mycobot_280/gripper_left3.dae"/>
		  	</geometry>
			<origin xyz = "0.012 0.0025 -0.012" rpy = " 0 0 0"/>
		</collision>
	</link>
	
	<link name="gripper_right1">
		<inertial>
			<origin xyz="0 0 0.0" rpy="0 0 0"/>
		  	<mass value="0.007"/>
		  	<inertia
				ixx="1e-6" ixy="0.0" ixz="0.0"
				iyy="1e-6" iyz="0.0"
				izz="1e-6"/>
		</inertial>
		<visual>
			<geometry>
		   		<mesh filename="file://$(find mycobot_description)/meshes/mycobot_280/gripper_right1.dae"/>
		  	</geometry>
			<origin xyz = "-0.039 -0.0133 -0.012 " rpy = " 0 0 0"/>
		</visual>
		<collision>
		  	<geometry>
		   		<mesh filename="file://$(find mycobot_description)/meshes/mycobot_280/gripper_right1.dae"/>
		  	</geometry>
			<origin xyz = "-0.039 -0.0133 -0.012 " rpy = " 0 0 0"/>
		</collision>
	</link>
	
	<link name="gripper_right2">
		<inertial>
			<origin xyz="0 0 0.0" rpy="0 0 0"/>
		  	<mass value="0.007"/>
		  	<inertia
				ixx="1e-6" ixy="0.0" ixz="0.0"
				iyy="1e-6" iyz="0.0"
				izz="1e-6"/>
		</inertial>
		<visual>
			<geometry>
		   		<mesh filename="file://$(find mycobot_description)/meshes/mycobot_280/gripper_right2.dae"/>
		 	</geometry>
			<origin xyz = "-0.005 -0.0195 -0.012 " rpy = " 0 0 0"/>
		</visual>
		<collision>
		  	<geometry>
		   		<mesh filename="file://$(find mycobot_description)/meshes/mycobot_280/gripper_right2.dae"/>
		  	</geometry>
			<origin xyz = "-0.005 -0.0195 -0.012 " rpy = " 0 0 0"/>
		</collision>
	</link>
	
	<link name="gripper_right3">
		<inertial>
			<origin xyz="0 0 0.0" rpy="0 0 0"/>
		  	<mass value="0.007"/>
		  	<inertia
				ixx="1e-6" ixy="0.0" ixz="0.0"
				iyy="1e-6" iyz="0.0"
				izz="1e-6"/>
		</inertial>
		<visual>
			<geometry>
		   		<mesh filename="file://$(find mycobot_description)/meshes/mycobot_280/gripper_right3.dae"/>
			</geometry>
			<origin xyz = "-0.012 0.0025 -0.012 " rpy = " 0 0 0"/>
		</visual>
		<collision>
		  	<geometry>
		   		<mesh filename="file://$(find mycobot_description)/meshes/mycobot_280/gripper_right3.dae"/>
		  	</geometry>
			<origin xyz = "-0.012 0.0025 -0.012" rpy = " 0 0 0"/>
		</collision>
	</link>
  

	<joint name="virtual_joint" type="fixed">
		<parent link="world"/>
		<child link="base_link"/>
		<origin xyz= "0 0 0" rpy = "0 0 0"/>  
	</joint>
	
        <joint name="base_link_to_link1" type="fixed">
            <parent link="base_link"/>
            <child link="link1"/>
            <origin xyz="0 0 0" rpy="0 0 0"/>
        </joint>

	<joint name="link1_to_link2" type="revolute">
		<axis xyz="0 0 1"/>
		<limit effort = "${effort}" lower = "-2.879793" upper = "2.879793" velocity = "${velocity}"/>
		<parent link="link1"/>
		<child link="link2"/>
	    <origin xyz= "0 0 0.13156" rpy = "0 0 ${pi/2}"/>  
        <dynamics damping="0.05" friction="0.05"/>
	</joint>

	<joint name="link2_to_link3" type="revolute">
		<axis xyz="0 0 1"/>
		<limit effort = "${effort}" lower = "-2.879793" upper = "2.879793" velocity = "${velocity}"/>
		<parent link="link2"/>
		<child link="link3"/>
		<origin xyz= "0 0 -0.001" rpy = "0 ${pi/2} ${-pi/2}"/>  
        <dynamics damping="0.205" friction="0.15"/>
	</joint>

	<joint name="link3_to_link4" type="revolute">
		<axis xyz=" 0 0 1"/>
		<limit effort = "${effort}" lower = "-2.879793" upper = "2.879793" velocity = "${velocity}"/>
		<parent link="link3"/>
		<child link="link4"/>
		<origin xyz= "-0.1104 0 0   " rpy = "0 0 0"/>
        <dynamics damping="0.21" friction="0.41"/>
	</joint>

	<joint name="link4_to_link5" type="revolute">
		<axis xyz=" 0 0 1"/>
		<limit effort = "${effort}" lower = "-2.879793" upper = "2.879793" velocity = "${velocity}"/>
		<parent link="link4"/>
		<child link="link5"/>
		<origin xyz= "-0.096 0 0.06062" rpy = "0 0 ${-pi/2}"/>
        <dynamics damping="0.10" friction="0.20"/>
	</joint>

	<joint name="link5_to_link6" type="revolute">
		<axis xyz=" 0 0 1"/>
		<limit effort = "${effort}" lower = "-2.879793" upper = "2.879793" velocity = "${velocity}"/>
		<parent link="link5"/>
		<child link="link6"/>
		<origin xyz= "0 -0.07318 0" rpy = "${pi/2} ${-pi/2} 0"/>
        <dynamics damping="0.01" friction="0.005"/>
	</joint>

	<joint name="link6_to_link6flange" type="revolute">
		<axis xyz=" 0 0 1"/>
		<limit effort = "${effort}" lower = "-3.05" upper = "3.05" velocity = "${velocity}"/>
		<parent link="link6"/>
		<child link="link6_flange"/>
		<origin xyz= "0 0.0456 0" rpy = "${-pi/2} 0 0"/>
        <dynamics damping="0.01" friction="0.005"/>
	</joint>

	<joint name="link6flange_to_gripper_base" type="fixed">
		<parent link="link6_flange"/>
		<child link="gripper_base"/>
		<origin xyz= "0 0 0.034" rpy = "1.579 0 0"/>
	</joint>

	<joint name="gripper_controller" type="revolute">
		<axis xyz="0 0 1"/>
		<limit effort = "${effort}" lower = "-0.7" upper = "0.15" velocity = "${velocity}"/>
		<parent link="gripper_base"/>
		<child link="gripper_left3"/>
		<origin xyz= "-0.012 0.005 0" rpy = "0 0 0"/> 
        <dynamics damping="0.01" friction="0.005"/>
	</joint>

	<joint name="gripper_base_to_gripper_left2" type="revolute">
		<axis xyz="0 0 1"/>
		<limit effort = "${effort}" lower = "-0.8" upper = "0.5" velocity = "${velocity}"/>
		<parent link="gripper_base"/>
		<child link="gripper_left2"/>
		<origin xyz= "-0.005 0.027 0" rpy = "0 0 0"/> 
		<mimic joint="gripper_controller" multiplier="1.0" offset="0" />
        <dynamics damping="0.01" friction="0.005"/>
	</joint>
	
	<joint name="gripper_left3_to_gripper_left1" type="revolute">
		<axis xyz="0 0 1"/>
		<limit effort = "${effort}" lower = "-0.5" upper = "0.5" velocity = "${velocity}"/>
		<parent link="gripper_left3"/>
		<child link="gripper_left1"/>
		<origin xyz= "-0.027 0.016 0" rpy = "0 0 0"/> 
		<mimic joint="gripper_controller" multiplier="-1.0" offset="0" />
        <dynamics damping="0.01" friction="0.005"/>
	</joint>
	
	<joint name="gripper_base_to_gripper_right3" type="revolute">
		<axis xyz="0 0 1"/>
		<limit effort = "${effort}" lower = "-0.15" upper = "0.7" velocity = "${velocity}"/>
		<parent link="gripper_base"/>
		<child link="gripper_right3"/>
		<origin xyz= "0.012 0.005 0" rpy = "0 0 0"/> 
		<mimic joint="gripper_controller" multiplier="-1.0" offset="0" />
        <dynamics damping="0.01" friction="0.005"/>
	</joint>
	
	<joint name="gripper_base_to_gripper_right2" type="revolute">
		<axis xyz="0 0 1"/>
		<limit effort = "${effort}" lower = "-0.5" upper = "0.8" velocity = "${velocity}"/>
		<parent link="gripper_base"/>
		<child link="gripper_right2"/>
		<origin xyz= "0.005 0.027 0" rpy = "0 0 0"/> 
		<mimic joint="gripper_controller" multiplier="-1.0" offset="0" />
        <dynamics damping="0.01" friction="0.005"/>
	</joint>
	
	<joint name="gripper_right3_to_gripper_right1" type="revolute">
		<axis xyz="0 0 1"/>
		<limit effort = "${effort}" lower = "-0.5" upper = "0.5" velocity = "${velocity}"/>
		<parent link="gripper_right3"/>
		<child link="gripper_right1"/>
		<origin xyz= "0.027 0.016 0" rpy = "0 0 0"/> 
		<mimic joint="gripper_controller" multiplier="1.0" offset="0" />
        <dynamics damping="0.01" friction="0.005"/>
	</joint>


	<link name="torso_link">
		<inertial>
		  <origin xyz="0 0 0.50" />
		  <mass value="2.5" />
		  <inertia ixx="0.8" ixy="0.0" ixz="0.0" iyy="0.8" iyz="0.0" izz="0.8" />
		</inertial>
		<visual name="holder">
		  <origin xyz="0 0 0.25" rpy="0 0 0" />
		  <material name="LightGrey">
			<color rgba="0.7 0.7 0.7 1.0"/>
		  </material>
		  <geometry>
			<cylinder radius="0.005" length="0.5"/>
		  </geometry>
		</visual>
		<visual name="base">
		  <origin xyz="0 0 0" rpy="0 0 0" />
		  <material name="LightGrey">
			<color rgba="0.7 0.7 0.7 1.0"/>
		  </material>
		  <geometry>
			<box size="0.15 0.10 0.06" />
		  </geometry>
		</visual>
		<collision name="holder">
		  <origin xyz="0 0 0.25" rpy="0 0 0" />
		  <geometry>
			<cylinder radius="0.005" length="0.6"/>
		  </geometry>
		</collision>
		<collision name="base">
		  <origin xyz="0 0 0.0" rpy="0 0 0" />
		  <geometry>
			<box size="0.15 0.10 0.06" />
		  </geometry>
		</collision>
	  </link>
	  
	  <joint name="base_link_to_torso_link" type="fixed">
		<parent link="base_link"/>
		<child link="torso_link"/>
		<origin xyz="0.22 -0.30 0" rpy="0 0 0"/>
	  </joint>
	  
	  <joint name="camera_head_joint" type="fixed">
		<parent link="torso_link"/>
		<child link="camera_head_link" />
		<origin xyz="0 0.01 0.50" rpy="0.0 ${camera_tilt_angle_deg * M_PI / 180} ${M_PI/2}"/>
	  </joint>
	  
	  <link name="camera_head_link">
		<visual>
		  <origin xyz="0 0 0" rpy="${M_PI/2} 0.0 ${M_PI/2}"/>
		  <geometry>
			<mesh filename="file://$(find hello_mtc_with_perception)/urdf/meshes/d435.stl" />
		  </geometry>
		  <material name="aluminum">
			<color rgba="0.5 0.5 0.5 1"/>
		  </material>
		</visual>
		<collision>
		  <origin xyz="0 0 0" rpy="0 0 0"/>
		  <geometry>
			<box size="${d435_cam_depth} ${d435_cam_width} ${d435_cam_height}"/>
		  </geometry>
		</collision>
		<inertial>
		  <mass value="0.072" />
		  <origin xyz="0 0 0" />
		  <inertia ixx="0.003881243" ixy="0.0" ixz="0.0" iyy="0.000498940" iyz="0.0" izz="0.003879257" />
		</inertial>
	  </link>
	
	  <joint name="camera_head_depth_joint" type="fixed">
		<origin xyz="0 0 0" rpy="0 0 0"/>
		<parent link="camera_head_link"/>
		<child link="camera_head_depth_frame" />
	  </joint>
	  <link name="camera_head_depth_frame"/>
	
	  <joint name="camera_head_depth_optical_joint" type="fixed">
		<origin xyz="0 0 0" rpy="${-M_PI/2} 0 ${-M_PI/2}" />
		<parent link="camera_head_depth_frame" />
		<child link="camera_head_depth_optical_frame" />
	  </joint>
	  <link name="camera_head_depth_optical_frame"/>
	
	  <joint name="camera_head_infra1_joint" type="fixed">
		<origin xyz="0 ${d435_cam_depth_to_infra1_offset} 0" rpy="0 0 0" />
		<parent link="camera_head_link" />
		<child link="camera_head_infra1_frame" />
	  </joint>
	  <link name="camera_head_infra1_frame"/>
	
	  <joint name="camera_head_infra1_optical_joint" type="fixed">
		<origin xyz="0 0 0" rpy="${-M_PI/2} 0 ${-M_PI/2}" />
		<parent link="camera_head_infra1_frame" />
		<child link="camera_head_infra1_optical_frame" />
	  </joint>
	  <link name="camera_head_infra1_optical_frame"/>
	
	  <joint name="camera_head_infra2_joint" type="fixed">
		<origin xyz="0 ${d435_cam_depth_to_infra2_offset} 0" rpy="0 0 0" />
		<parent link="camera_head_link" />
		<child link="camera_head_infra2_frame" />
	  </joint>
	  <link name="camera_head_infra2_frame"/>
	
	  <joint name="camera_head_infra2_optical_joint" type="fixed">
		<origin xyz="0 0 0" rpy="${-M_PI/2} 0 ${-M_PI/2}" />
		<parent link="camera_head_infra2_frame" />
		<child link="camera_head_infra2_optical_frame" />
	  </joint>
	  <link name="camera_head_infra2_optical_frame"/>
	
	  <joint name="camera_head_color_joint" type="fixed">
		<origin xyz="0 ${d435_cam_depth_to_color_offset} 0" rpy="0 0 0" />
		<parent link="camera_head_link" />
		<child link="camera_head_color_frame" />
	  </joint>
	  <link name="camera_head_color_frame"/>
	
	  <joint name="camera_head_color_optical_joint" type="fixed">
		<origin xyz="0 0 0" rpy="${-M_PI/2} 0 ${-M_PI/2}" />
		<parent link="camera_head_color_frame" />
		<child link="camera_head_color_optical_frame" />
	  </joint>
	  <link name="camera_head_color_optical_frame"/>
	
	  <gazebo reference="camera_head_link">
		<sensor name="camera_head" type="rgbd_camera">
		  <camera>
			<horizontal_fov>1.5184</horizontal_fov>
			<image>
			  <width>424</width>
			  <height>240</height>
			</image>
			<clip>
			  <near>0.05</near>
			  <far>1.5</far>
			</clip>
			<optical_frame_id>camera_head_depth_optical_frame</optical_frame_id>
		  </camera>
		  <always_on>1</always_on>
		  <gz_frame_id>camera_head_link</gz_frame_id>
		  <topic>camera_head</topic>
		  <update_rate>5</update_rate>
		  <visualize>true</visualize>
		</sensor>
	  </gazebo>



    <gazebo>
        <plugin filename="ignition-gazebo-joint-state-publisher-system" name="ignition::gazebo::systems::JointStatePublisher">
            <topic>joint_states</topic>
        </plugin>    
    </gazebo>      

    <gazebo>
        <plugin filename="ignition-gazebo-joint-position-controller-system" name="ignition::gazebo::systems::JointPositionController">
            <joint_name>link1_to_link2</joint_name>
        </plugin>    
    </gazebo>  
    <gazebo>
        <plugin filename="ignition-gazebo-joint-position-controller-system" name="ignition::gazebo::systems::JointPositionController">
            <joint_name>link2_to_link3</joint_name>
        </plugin>    
    </gazebo>  
    <gazebo>
        <plugin filename="ignition-gazebo-joint-position-controller-system" name="ignition::gazebo::systems::JointPositionController">
            <joint_name>link3_to_link4</joint_name>
        </plugin>    
    </gazebo>  
    <gazebo>
        <plugin filename="ignition-gazebo-joint-position-controller-system" name="ignition::gazebo::systems::JointPositionController">
            <joint_name>link4_to_link5</joint_name>
        </plugin>    
    </gazebo>  
    <gazebo>
        <plugin filename="ignition-gazebo-joint-position-controller-system" name="ignition::gazebo::systems::JointPositionController">
            <joint_name>link5_to_link6</joint_name>
        </plugin>    
    </gazebo>  
    <gazebo>
        <plugin filename="ignition-gazebo-joint-position-controller-system" name="ignition::gazebo::systems::JointPositionController">
            <joint_name>link6_to_link6flange</joint_name>
        </plugin>    
    </gazebo>  
    <gazebo>
        <plugin filename="ignition-gazebo-joint-position-controller-system" name="ignition::gazebo::systems::JointPositionController">
            <joint_name>gripper_controller</joint_name>
        </plugin>    
    </gazebo>  
    <gazebo>
        <plugin filename="ignition-gazebo-joint-position-controller-system" name="ignition::gazebo::systems::JointPositionController">
            <joint_name>gripper_base_to_gripper_left2</joint_name>
        </plugin>    
    </gazebo>  
    <gazebo>
        <plugin filename="ignition-gazebo-joint-position-controller-system" name="ignition::gazebo::systems::JointPositionController">
            <joint_name>gripper_left3_to_gripper_left1</joint_name>
        </plugin>    
    </gazebo>  
    <gazebo>
        <plugin filename="ignition-gazebo-joint-position-controller-system" name="ignition::gazebo::systems::JointPositionController">
            <joint_name>gripper_base_to_gripper_right3</joint_name>
        </plugin>    
    </gazebo>  
    <gazebo>
        <plugin filename="ignition-gazebo-joint-position-controller-system" name="ignition::gazebo::systems::JointPositionController">
            <joint_name>gripper_base_to_gripper_right2</joint_name>
        </plugin>    
    </gazebo>  
    <gazebo>
        <plugin filename="ignition-gazebo-joint-position-controller-system" name="ignition::gazebo::systems::JointPositionController">
            <joint_name>gripper_right3_to_gripper_right1</joint_name>
        </plugin>    
    </gazebo>       

</robot>
